2018-02-22 23:39:41,970 ERROR: Exception on /edit_profile [POST] [in /media/alex/www/python/microblog/venv/lib/python3.5/site-packages/flask/app.py:1560]
Traceback (most recent call last):
  File "/media/alex/www/python/microblog/venv/lib/python3.5/site-packages/sqlalchemy/engine/base.py", line 1193, in _execute_context
    context)
  File "/media/alex/www/python/microblog/venv/lib/python3.5/site-packages/sqlalchemy/engine/default.py", line 507, in do_execute
    cursor.execute(statement, parameters)
sqlite3.IntegrityError: UNIQUE constraint failed: user.username

The above exception was the direct cause of the following exception:

Traceback (most recent call last):
  File "/media/alex/www/python/microblog/venv/lib/python3.5/site-packages/flask/app.py", line 1982, in wsgi_app
    response = self.full_dispatch_request()
  File "/media/alex/www/python/microblog/venv/lib/python3.5/site-packages/flask/app.py", line 1614, in full_dispatch_request
    rv = self.handle_user_exception(e)
  File "/media/alex/www/python/microblog/venv/lib/python3.5/site-packages/flask/app.py", line 1517, in handle_user_exception
    reraise(exc_type, exc_value, tb)
  File "/media/alex/www/python/microblog/venv/lib/python3.5/site-packages/flask/_compat.py", line 33, in reraise
    raise value
  File "/media/alex/www/python/microblog/venv/lib/python3.5/site-packages/flask/app.py", line 1612, in full_dispatch_request
    rv = self.dispatch_request()
  File "/media/alex/www/python/microblog/venv/lib/python3.5/site-packages/flask/app.py", line 1598, in dispatch_request
    return self.view_functions[rule.endpoint](**req.view_args)
  File "/media/alex/www/python/microblog/venv/lib/python3.5/site-packages/flask_login/utils.py", line 261, in decorated_view
    return func(*args, **kwargs)
  File "/media/alex/www/python/microblog/app/routes.py", line 84, in edit_profile
    db.session.commit()
  File "/media/alex/www/python/microblog/venv/lib/python3.5/site-packages/sqlalchemy/orm/scoping.py", line 153, in do
    return getattr(self.registry(), name)(*args, **kwargs)
  File "/media/alex/www/python/microblog/venv/lib/python3.5/site-packages/sqlalchemy/orm/session.py", line 943, in commit
    self.transaction.commit()
  File "/media/alex/www/python/microblog/venv/lib/python3.5/site-packages/sqlalchemy/orm/session.py", line 467, in commit
    self._prepare_impl()
  File "/media/alex/www/python/microblog/venv/lib/python3.5/site-packages/sqlalchemy/orm/session.py", line 447, in _prepare_impl
    self.session.flush()
  File "/media/alex/www/python/microblog/venv/lib/python3.5/site-packages/sqlalchemy/orm/session.py", line 2243, in flush
    self._flush(objects)
  File "/media/alex/www/python/microblog/venv/lib/python3.5/site-packages/sqlalchemy/orm/session.py", line 2369, in _flush
    transaction.rollback(_capture_exception=True)
  File "/media/alex/www/python/microblog/venv/lib/python3.5/site-packages/sqlalchemy/util/langhelpers.py", line 66, in __exit__
    compat.reraise(exc_type, exc_value, exc_tb)
  File "/media/alex/www/python/microblog/venv/lib/python3.5/site-packages/sqlalchemy/util/compat.py", line 187, in reraise
    raise value
  File "/media/alex/www/python/microblog/venv/lib/python3.5/site-packages/sqlalchemy/orm/session.py", line 2333, in _flush
    flush_context.execute()
  File "/media/alex/www/python/microblog/venv/lib/python3.5/site-packages/sqlalchemy/orm/unitofwork.py", line 391, in execute
    rec.execute(self)
  File "/media/alex/www/python/microblog/venv/lib/python3.5/site-packages/sqlalchemy/orm/unitofwork.py", line 556, in execute
    uow
  File "/media/alex/www/python/microblog/venv/lib/python3.5/site-packages/sqlalchemy/orm/persistence.py", line 177, in save_obj
    mapper, table, update)
  File "/media/alex/www/python/microblog/venv/lib/python3.5/site-packages/sqlalchemy/orm/persistence.py", line 768, in _emit_update_statements
    execute(statement, multiparams)
  File "/media/alex/www/python/microblog/venv/lib/python3.5/site-packages/sqlalchemy/engine/base.py", line 948, in execute
    return meth(self, multiparams, params)
  File "/media/alex/www/python/microblog/venv/lib/python3.5/site-packages/sqlalchemy/sql/elements.py", line 269, in _execute_on_connection
    return connection._execute_clauseelement(self, multiparams, params)
  File "/media/alex/www/python/microblog/venv/lib/python3.5/site-packages/sqlalchemy/engine/base.py", line 1060, in _execute_clauseelement
    compiled_sql, distilled_params
  File "/media/alex/www/python/microblog/venv/lib/python3.5/site-packages/sqlalchemy/engine/base.py", line 1200, in _execute_context
    context)
  File "/media/alex/www/python/microblog/venv/lib/python3.5/site-packages/sqlalchemy/engine/base.py", line 1413, in _handle_dbapi_exception
    exc_info
  File "/media/alex/www/python/microblog/venv/lib/python3.5/site-packages/sqlalchemy/util/compat.py", line 203, in raise_from_cause
    reraise(type(exception), exception, tb=exc_tb, cause=cause)
  File "/media/alex/www/python/microblog/venv/lib/python3.5/site-packages/sqlalchemy/util/compat.py", line 186, in reraise
    raise value.with_traceback(tb)
  File "/media/alex/www/python/microblog/venv/lib/python3.5/site-packages/sqlalchemy/engine/base.py", line 1193, in _execute_context
    context)
  File "/media/alex/www/python/microblog/venv/lib/python3.5/site-packages/sqlalchemy/engine/default.py", line 507, in do_execute
    cursor.execute(statement, parameters)
sqlalchemy.exc.IntegrityError: (sqlite3.IntegrityError) UNIQUE constraint failed: user.username [SQL: 'UPDATE user SET username=?, about_me=? WHERE user.id = ?'] [parameters: ('alex', 'hello', 1)] (Background on this error at: http://sqlalche.me/e/gkpj)
2018-02-23 15:07:38,794 INFO: Microblog startup [in /media/alex/www/python/microblog/app/__init__.py:39]
2018-02-23 16:07:45,023 INFO: Microblog startup [in /media/alex/www/python/microblog/app/__init__.py:39]
2018-02-23 16:09:51,567 INFO: Microblog startup [in /media/alex/www/python/microblog/app/__init__.py:39]
2018-02-23 16:10:12,352 INFO: Microblog startup [in /media/alex/www/python/microblog/app/__init__.py:39]
2018-02-23 22:32:43,680 INFO: Microblog startup [in /media/alex/www/python/microblog/app/__init__.py:39]
2018-02-23 22:52:27,380 INFO: Microblog startup [in /media/alex/www/python/microblog/app/__init__.py:39]
2018-02-25 15:56:03,180 INFO: Microblog startup [in /media/alex/www/python/microblog/app/__init__.py:39]
2018-02-25 16:28:52,452 INFO: Microblog startup [in /media/alex/www/python/microblog/app/__init__.py:39]
2018-02-26 23:15:34,756 INFO: Microblog startup [in /media/alex/www/python/microblog/app/__init__.py:39]
2018-02-26 23:36:44,679 INFO: Microblog startup [in /media/alex/www/python/microblog/app/__init__.py:39]
2018-02-27 00:10:07,486 INFO: Microblog startup [in /media/alex/www/python/microblog/app/__init__.py:39]
2018-02-27 00:18:45,903 INFO: Microblog startup [in /media/alex/www/python/microblog/app/__init__.py:39]
2018-02-27 00:20:33,672 INFO: Microblog startup [in /media/alex/www/python/microblog/app/__init__.py:39]
2018-02-27 00:20:35,231 ERROR: Exception on /user/alex [GET] [in /media/alex/www/python/microblog/venv/lib/python3.5/site-packages/flask/app.py:1560]
Traceback (most recent call last):
  File "/media/alex/www/python/microblog/venv/lib/python3.5/site-packages/flask/app.py", line 1982, in wsgi_app
    response = self.full_dispatch_request()
  File "/media/alex/www/python/microblog/venv/lib/python3.5/site-packages/flask/app.py", line 1614, in full_dispatch_request
    rv = self.handle_user_exception(e)
  File "/media/alex/www/python/microblog/venv/lib/python3.5/site-packages/flask/app.py", line 1517, in handle_user_exception
    reraise(exc_type, exc_value, tb)
  File "/media/alex/www/python/microblog/venv/lib/python3.5/site-packages/flask/_compat.py", line 33, in reraise
    raise value
  File "/media/alex/www/python/microblog/venv/lib/python3.5/site-packages/flask/app.py", line 1612, in full_dispatch_request
    rv = self.dispatch_request()
  File "/media/alex/www/python/microblog/venv/lib/python3.5/site-packages/flask/app.py", line 1598, in dispatch_request
    return self.view_functions[rule.endpoint](**req.view_args)
  File "/media/alex/www/python/microblog/venv/lib/python3.5/site-packages/flask_login/utils.py", line 261, in decorated_view
    return func(*args, **kwargs)
  File "/media/alex/www/python/microblog/app/routes.py", line 87, in user
    next_url = url_for('user', page=posts.next_num) if posts.has_next else None
  File "/media/alex/www/python/microblog/venv/lib/python3.5/site-packages/flask/helpers.py", line 333, in url_for
    return appctx.app.handle_url_build_error(error, endpoint, values)
  File "/media/alex/www/python/microblog/venv/lib/python3.5/site-packages/flask/app.py", line 1805, in handle_url_build_error
    reraise(exc_type, exc_value, tb)
  File "/media/alex/www/python/microblog/venv/lib/python3.5/site-packages/flask/_compat.py", line 33, in reraise
    raise value
  File "/media/alex/www/python/microblog/venv/lib/python3.5/site-packages/flask/helpers.py", line 323, in url_for
    force_external=external)
  File "/media/alex/www/python/microblog/venv/lib/python3.5/site-packages/werkzeug/routing.py", line 1776, in build
    raise BuildError(endpoint, values, method, self)
werkzeug.routing.BuildError: Could not build url for endpoint 'user' with values ['page']. Did you forget to specify values ['username']?
